Workbook

Sheet README
B2: YPOG — Controlling Dashboard
B3: Business partnering, pricing, planning and reporting overview — figures in EUR
B6: ABOUT THE DATA
B7: All figures in this workbook (hours, revenue, costs, FTE, names) are illustrative sample data.
B8: They do not represent actual YPOG data.
B10: CONTENTS
B11: • Dashboard — revenue, profitability, utilization, realization, rates and unbilled services; filters for year and practice area
B12: • Pricing_Analysis — list rate vs. realized rate, write-offs, unbilled services and a what-if pricing scenario
B13: • Business_Case — investment case for a new tech product: NPV, IRR, ROI, payback, scenarios and sensitivity table
B14: • Planning_Forecast — FY2026 budget vs. actual/forecast, full-year outlook and cumulative view
B15: • Action_Tracker — findings translated into options for action, owners, status and expected impact
B16: • BI_Requirements — specification example for Power BI dashboards (KPI definitions, sources, refresh, audience)
... B24: • Profit — revenue less personnel cost and other cost (simplified view)

Sheet Dashboard
B2: YPOG — CONTROLLING DASHBOARD
B3: Business partnering, pricing and planning overview | Illustrative sample data (EUR)
B4: =HYPERLINK("#'README'!A1","ⓘ README") -> ⓘ README | C4: =HYPERLINK("#'Pricing_Analysis'!A1","€ PRICING") -> € PRICING | D4: =HYPERLINK("#'Business_Case'!A1","▤ BUSINESS CASE") -> ▤ BUSINESS CASE | E4: =HYPERLINK("#'Planning_Forecast'!A1","▦ PLANNING") -> ▦ PLANNING | F4: =HYPERLINK("#'Action_Tracker'!A1","✔ ACTIONS") -> ✔ ACTIONS | G4: =HYPERLINK("#'BI_Requirements'!A1","▣ BI SPEC") -> ▣ BI SPEC
B5: Year: | D5: 2026 | G5: Practice area: | H5: All | J5: ← filters
B7: REVENUE | C7: VS. BUDGET | D7: PROFIT | E7: PROFIT MARGIN | F7: UTILIZATION | G7: REALIZATION | H7: REALIZED RATE | I7: AVG FTE | J7: REVENUE PER FTE | K7: UNBILLED WIP
B8: =Calc_Engine!B4 -> 68275620 | C8: =Calc_Engine!B6 -> 0.0011176051 | D8: =Calc_Engine!B7 -> 18375090 | E8: =Calc_Engine!B8 -> 0.26913106 | F8: =Calc_Engine!B12 -> 0.68417529 | G8: =Calc_Engine!B13 -> 0.91102062 | H8: =Calc_Engine!B14 -> 349.17161 | I8: =Calc_Engine!B15 -> 182.74167 | J8: =Calc_Engine!B16 -> 373618.24 | K8: =Calc_Engine!B18 -> 2869100
B10: ="▸ Revenue "&ROUND(Calc_Engine!B4/1000000,1)&" M € ("&IF(Calc_Engine!B6>=0,"+","")&ROUND(Calc_Engine!B6*100,1)&"% vs. budget) · utilization "&ROUND(Calc_Engine!B12*100,0)&"% · realization "&ROUND(Calc_Engine!B13*100,0)&"% · unbilled WIP "&ROUND(Calc_Engine!B18/1000000,1)&" M €" -> ▸ Revenue 68.3 M € (+0.1% vs. budget) · utilization 68% · realization 91% · unbilled WIP 2.9 M €
B11: WHERE EACH REVENUE EURO GOES (selected filters) | H11: PRICING HEALTH
B12: ="Revenue"&CHAR(10)&ROUND(Calc_Engine!B4/1000000,1)&" M €" -> Revenue 68.3 M € | C12: ="Personnel"&CHAR(10)&ROUND(-Calc_Engine!B19/1000000,1)&" M €" -> Personnel -34.9 M € | D12: ="Other costs"&CHAR(10)&ROUND(-Calc_Engine!B20/1000000,1)&" M €" -> Other costs -15 M € | E12: ="Profit"&CHAR(10)&ROUND(Calc_Engine!B7/1000000,1)&" M €" -> Profit 18.4 M € | H12: ="Utilization "&REPT("█",ROUND(Calc_Engine!B12*20,0))&" "&ROUND(Calc_Engine!B12*100,0)&"%"&CHAR(10)&"Realization "&REPT("█",ROUND(Calc_Engine!B13*20,0))&" "&ROUND(Calc_Engine!B13*100,0)&"%"&CHAR(10)&"Write-offs "&REPT("█",ROUND(Calc_Engine!B22/MAX(1,Calc_Engine!B21)*200,0))&" "&ROUND(Calc_Engine!B22/MAX(1,Calc_Engine!B21)*100,1)&"% of list value" -> Utilization ██████████████ 68% Realization ██████████████████ 91% Write-offs ██████████████████ 8.9% of list value
B15: Monthly Revenue — Actual, Forecast vs. Budget | G15: Utilization & Realization by Month
B37: Cost Structure | E37: Pricing Matrix — Utilization vs. Realized Rate (bubble = revenue)
B59: Profit Margin by Practice Area (selected year) | G59: Revenue Leakage: List Value to Realized Revenue

Sheet Pricing_Analysis
A1: PRICING, RATES & UNBILLED SERVICES — BY PRACTICE AREA
A2: =HYPERLINK("#'Dashboard'!A1","◀ Back to Dashboard") -> ◀ Back to Dashboard | C2: ="Year shown: "&Dashboard!$D$5&" (change on Dashboard)" -> Year shown: 2026 (change on Dashboard)
A4: RATE CARD & REALIZATION
A5: Practice Area | B5: List Rate (EUR/h) | C5: Billable Hours | D5: Invoiced Hours | E5: Realization % | F5: Revenue | G5: Realized Rate (EUR/h) | H5: Rate Realization % | I5: Write-off Hours | J5: Write-off Value | K5: Profit | L5: Profit Margin % | M5: Latest WIP | N5: Scenario Revenue | O5: Δ Revenue
A6: Private Equity & VC | B6: 390 | C6: =SUMIFS(Monthly_Data!$I$3:$I$146,Monthly_Data!$B$3:$B$146,Dashboard!$D$5,Monthly_Data!$E$3:$E$146,A6) -> 49281 | D6: =SUMIFS(Monthly_Data!$J$3:$J$146,Monthly_Data!$B$3:$B$146,Dashboard!$D$5,Monthly_Data!$E$3:$E$146,A6) -> 45676 | E6: =IFERROR(D6/C6,0) -> 0.92684808 | F6: =SUMIFS(Monthly_Data!$K$3:$K$146,Monthly_Data!$B$3:$B$146,Dashboard!$D$5,Monthly_Data!$E$3:$E$146,A6) -> 16911600 | G6: =IFERROR(F6/D6,0) -> 370.25134 | H6: =IFERROR(G6/B6,0) -> 0.9493624 | I6: =C6-D6 -> 3605 | J6: =SUMIFS(Monthly_Data!$R$3:$R$146,Monthly_Data!$B$3:$B$146,Dashboard!$D$5,Monthly_Data!$E$3:$E$146,A6) -> 1405950 | K6: =SUMIFS(Monthly_Data!$S$3:$S$146,Monthly_Data!$B$3:$B$146,Dashboard!$D$5,Monthly_Data!$E$3:$E$146,A6) -> 5676570 | L6: =IFERROR(K6/F6,0) -> 0.33566132 | M6: =SUMIFS(Monthly_Data!$O$3:$O$146,Monthly_Data!$B$3:$B$146,Dashboard!$D$5,Monthly_Data!$C$3:$C$146,Calc_Engine!$B$17,Monthly_Data!$E$3:$E$146,A6) -> 586400 | N6: =C6*MIN(1,E6+$B$17)*B6*(1+$B$16)*H6 -> 17967588 | O6: =N6-F6 -> 1055988.2
A7: Funds & Asset Mgmt | B7: 370 | C7: =SUMIFS(Monthly_Data!$I$3:$I$146,Monthly_Data!$B$3:$B$146,Dashboard!$D$5,Monthly_Data!$E$3:$E$146,A7) -> 37545 | D7: =SUMIFS(Monthly_Data!$J$3:$J$146,Monthly_Data!$B$3:$B$146,Dashboard!$D$5,Monthly_Data!$E$3:$E$146,A7) -> 34650 | E7: =IFERROR(D7/C7,0) -> 0.92289253 | F7: =SUMIFS(Monthly_Data!$K$3:$K$146,Monthly_Data!$B$3:$B$146,Dashboard!$D$5,Monthly_Data!$E$3:$E$146,A7) -> 12110320 | G7: =IFERROR(F7/D7,0) -> 349.50418 | H7: =IFERROR(G7/B7,0) -> 0.9446059 | I7: =C7-D7 -> 2895 | J7: =SUMIFS(Monthly_Data!$R$3:$R$146,Monthly_Data!$B$3:$B$146,Dashboard!$D$5,Monthly_Data!$E$3:$E$146,A7) -> 1071150 | K7: =SUMIFS(Monthly_Data!$S$3:$S$146,Monthly_Data!$B$3:$B$146,Dashboard!$D$5,Monthly_Data!$E$3:$E$146,A7) -> 3279860 | L7: =IFERROR(K7/F7,0) -> 0.27083182 | M7: =SUMIFS(Monthly_Data!$O$3:$O$146,Monthly_Data!$B$3:$B$146,Dashboard!$D$5,Monthly_Data!$C$3:$C$146,Calc_Engine!$B$17,Monthly_Data!$E$3:$E$146,A7) -> 662400 | N7: =C7*MIN(1,E7+$B$17)*B7*(1+$B$16)*H7 -> 12867673 | O7: =N7-F7 -> 757353.2
A8: Tax | B8: 340 | C8: =SUMIFS(Monthly_Data!$I$3:$I$146,Monthly_Data!$B$3:$B$146,Dashboard!$D$5,Monthly_Data!$E$3:$E$146,A8) -> 31591 | D8: =SUMIFS(Monthly_Data!$J$3:$J$146,Monthly_Data!$B$3:$B$146,Dashboard!$D$5,Monthly_Data!$E$3:$E$146,A8) -> 28491 | E8: =IFERROR(D8/C8,0) -> 0.90187079 | F8: =SUMIFS(Monthly_Data!$K$3:$K$146,Monthly_Data!$B$3:$B$146,Dashboard!$D$5,Monthly_Data!$E$3:$E$146,A8) -> 8940620 | G8: =IFERROR(F8/D8,0) -> 313.80506 | H8: =IFERROR(G8/B8,0) -> 0.92295606 | I8: =C8-D8 -> 3100 | J8: =SUMIFS(Monthly_Data!$R$3:$R$146,Monthly_Data!$B$3:$B$146,Dashboard!$D$5,Monthly_Data!$E$3:$E$146,A8) -> 1054000 | K8: =SUMIFS(Monthly_Data!$S$3:$S$146,Monthly_Data!$B$3:$B$146,Dashboard!$D$5,Monthly_Data!$E$3:$E$146,A8) -> 1571200 | L8: =IFERROR(K8/F8,0) -> 0.17573725 | M8: =SUMIFS(Monthly_Data!$O$3:$O$146,Monthly_Data!$B$3:$B$146,Dashboard!$D$5,Monthly_Data!$C$3:$C$146,Calc_Engine!$B$17,Monthly_Data!$E$3:$E$146,A8) -> 391200 | N8: =C8*MIN(1,E8+$B$17)*B8*(1+$B$16)*H8 -> 9504443.8 | O8: =N8-F8 -> 563823.85
A9: M&A / Transactions | B9: 410 | C9: =SUMIFS(Monthly_Data!$I$3:$I$146,Monthly_Data!$B$3:$B$146,Dashboard!$D$5,Monthly_Data!$E$3:$E$146,A9) -> 54617 | D9: =SUMIFS(Monthly_Data!$J$3:$J$146,Monthly_Data!$B$3:$B$146,Dashboard!$D$5,Monthly_Data!$E$3:$E$146,A9) -> 48853 | E9: =IFERROR(D9/C9,0) -> 0.89446509 | F9: =SUMIFS(Monthly_Data!$K$3:$K$146,Monthly_Data!$B$3:$B$146,Dashboard!$D$5,Monthly_Data!$E$3:$E$146,A9) -> 17827750 | G9: =IFERROR(F9/D9,0) -> 364.92641 | H9: =IFERROR(G9/B9,0) -> 0.89006442 | I9: =C9-D9 -> 5764 | J9: =SUMIFS(Monthly_Data!$R$3:$R$146,Monthly_Data!$B$3:$B$146,Dashboard!$D$5,Monthly_Data!$E$3:$E$146,A9) -> 2363240 | K9: =SUMIFS(Monthly_Data!$S$3:$S$146,Monthly_Data!$B$3:$B$146,Dashboard!$D$5,Monthly_Data!$E$3:$E$146,A9) -> 5434650 | L9: =IFERROR(K9/F9,0) -> 0.30484217 | M9: =SUMIFS(Monthly_Data!$O$3:$O$146,Monthly_Data!$B$3:$B$146,Dashboard!$D$5,Monthly_Data!$C$3:$C$146,Calc_Engine!$B$17,Monthly_Data!$E$3:$E$146,A9) -> 576900 | N9: =C9*MIN(1,E9+$B$17)*B9*(1+$B$16)*H9 -> 18955429 | O9: =N9-F9 -> 1127678.7
A10: Regulatory & Fin. Services | B10: 355 | C10: =SUMIFS(Monthly_Data!$I$3:$I$146,Monthly_Data!$B$3:$B$146,Dashboard!$D$5,Monthly_Data!$E$3:$E$146,A10) -> 25937 | D10: =SUMIFS(Monthly_Data!$J$3:$J$146,Monthly_Data!$B$3:$B$146,Dashboard!$D$5,Monthly_Data!$E$3:$E$146,A10) -> 24263 | E10: =IFERROR(D10/C10,0) -> 0.935459 | F10: =SUMIFS(Monthly_Data!$K$3:$K$146,Monthly_Data!$B$3:$B$146,Dashboard!$D$5,Monthly_Data!$E$3:$E$146,A10) -> 8324150 | G10: =IFERROR(F10/D10,0) -> 343.08 | H10: =IFERROR(G10/B10,0) -> 0.96642253 | I10: =C10-D10 -> 1674 | J10: =SUMIFS(Monthly_Data!$R$3:$R$146,Monthly_Data!$B$3:$B$146,Dashboard!$D$5,Monthly_Data!$E$3:$E$146,A10) -> 594270 | K10: =SUMIFS(Monthly_Data!$S$3:$S$146,Monthly_Data!$B$3:$B$146,Dashboard!$D$5,Monthly_Data!$E$3:$E$146,A10) -> 2013360 | L10: =IFERROR(K10/F10,0) -> 0.24186974 | M10: =SUMIFS(Monthly_Data!$O$3:$O$146,Monthly_Data!$B$3:$B$146,Dashboard!$D$5,Monthly_Data!$C$3:$C$146,Calc_Engine!$B$17,Monthly_Data!$E$3:$E$146,A10) -> 444500 | N10: =C10*MIN(1,E10+$B$17)*B10*(1+$B$16)*H10 -> 8842204.1 | O10: =N10-F10 -> 518054.09
A11: Tech & Data | B11: 330 | C11: =SUMIFS(Monthly_Data!$I$3:$I$146,Monthly_Data!$B$3:$B$146,Dashboard!$D$5,Monthly_Data!$E$3:$E$146,A11) -> 15663 | D11: =SUMIFS(Monthly_Data!$J$3:$J$146,Monthly_Data!$B$3:$B$146,Dashboard!$D$5,Monthly_Data!$E$3:$E$146,A11) -> 13603 | E11: =IFERROR(D11/C11,0) -> 0.86847986 | F11: =SUMIFS(Monthly_Data!$K$3:$K$146,Monthly_Data!$B$3:$B$146,Dashboard!$D$5,Monthly_Data!$E$3:$E$146,A11) -> 4161180 | G11: =IFERROR(F11/D11,0) -> 305.90164 | H11: =IFERROR(G11/B11,0) -> 0.92697466 | I11: =C11-D11 -> 2060 | J11: =SUMIFS(Monthly_Data!$R$3:$R$146,Monthly_Data!$B$3:$B$146,Dashboard!$D$5,Monthly_Data!$E$3:$E$146,A11) -> 679800 | K11: =SUMIFS(Monthly_Data!$S$3:$S$146,Monthly_Data!$B$3:$B$146,Dashboard!$D$5,Monthly_Data!$E$3:$E$146,A11) -> 399450 | L11: =IFERROR(K11/F11,0) -> 0.095994405 | M11: =SUMIFS(Monthly_Data!$O$3:$O$146,Monthly_Data!$B$3:$B$146,Dashboard!$D$5,Monthly_Data!$C$3:$C$146,Calc_Engine!$B$17,Monthly_Data!$E$3:$E$146,A11) -> 207700 | N11: =C11*MIN(1,E11+$B$17)*B11*(1+$B$16)*H11 -> 4427287 | O11: =N11-F11 -> 266107.02
A12: Total / weighted | C12: =SUM(C6:C11) -> 214634 | D12: =SUM(D6:D11) -> 195536 | E12: =IFERROR(D12/C12,0) -> 0.91102062 | F12: =SUM(F6:F11) -> 68275620 | G12: =IFERROR(F12/D12,0) -> 349.17161 | H12: =IFERROR(G12/SUMPRODUCT(B6:B11,D6:D11)*SUM(D6:D11),0) -> 0.9295123 | I12: =SUM(I6:I11) -> 19098 | J12: =SUM(J6:J11) -> 7168410 | K12: =SUM(K6:K11) -> 18375090 | L12: =IFERROR(K12/F12,0) -> 0.26913106 | M12: =SUM(M6:M11) -> 2869100 | N12: =SUM(N6:N11) -> 72564625 | O12: =SUM(O6:O11) -> 4289005
A15: WHAT-IF: PRICING SCENARIO
A16: Rate card uplift | B16: 0.04 | D16: Scenario logic: scenario revenue = billable hours × (realization + improvement) × list rate × (1 + uplift) × current rate realization.
A17: Realization improvement (percentage points) | B17: 0.02
A18: Variable cost share of additional revenue | B18: 0.2
A20: Additional revenue (scenario) | B20: =O12 -> 4289005
A21: Additional profit (scenario) | B21: =B20*(1-B18) -> 3431204
A22: Scenario revenue vs. current | B22: =IFERROR(B20/F12,0) -> 0.062818983

Sheet Business_Case
A1: BUSINESS CASE — NEW TECH PRODUCT (investment, ROI, NPV)
A2: =HYPERLINK("#'Dashboard'!A1","◀ Back to Dashboard") -> ◀ Back to Dashboard
A4: ASSUMPTIONS
A5: Initial investment (year 0) | B5: 650000 | E5: Scenario | F5: Revenue factor
A6: Annual running cost (from year 1) | B6: 120000 | E6: Conservative | F6: 0.75
A7: Discount rate | B7: 0.08 | E7: Base | F7: 1
A8: Scenario | B8: Base | E8: Optimistic | F8: 1.25
A9: Revenue multiplier (from scenario) | B9: =INDEX($F$6:$F$8,MATCH($B$8,$E$6:$E$8,0)) -> 1
A12: EUR | B12: 0 | C12: 1 | D12: 2 | E12: 3 | F12: 4 | G12: 5
A13: Base-case revenue | B13: 0 | C13: 150000 | D13: 380000 | E13: 620000 | F13: 800000 | G13: 900000
A14: Scenario revenue | B14: =B13*$B$9 -> 0 | C14: =C13*$B$9 -> 150000 | D14: =D13*$B$9 -> 380000 | E14: =E13*$B$9 -> 620000 | F14: =F13*$B$9 -> 800000 | G14: =G13*$B$9 -> 900000
A15: Running cost | B15: =-IF(B$12>=1,$B$6,0) -> 0 | C15: =-IF(C$12>=1,$B$6,0) -> -120000 | D15: =-IF(D$12>=1,$B$6,0) -> -120000 | E15: =-IF(E$12>=1,$B$6,0) -> -120000 | F15: =-IF(F$12>=1,$B$6,0) -> -120000 | G15: =-IF(G$12>=1,$B$6,0) -> -120000
A16: Investment | B16: =-IF(B$12=0,$B$5,0) -> -650000 | C16: =-IF(C$12=0,$B$5,0) -> 0 | D16: =-IF(D$12=0,$B$5,0) -> 0 | E16: =-IF(E$12=0,$B$5,0) -> 0 | F16: =-IF(F$12=0,$B$5,0) -> 0 | G16: =-IF(G$12=0,$B$5,0) -> 0
A17: Net cash flow | B17: =B14+B15+B16 -> -650000 | C17: =C14+C15+C16 -> 30000 | D17: =D14+D15+D16 -> 260000 | E17: =E14+E15+E16 -> 500000 | F17: =F14+F15+F16 -> 680000 | G17: =G14+G15+G16 -> 780000
A18: Cumulative cash flow | B18: =B17 -> -650000 | C18: =B18+C17 -> -620000 | D18: =C18+D17 -> -360000 | E18: =D18+E17 -> 140000 | F18: =E18+F17 -> 820000 | G18: =F18+G17 -> 1600000
A19: Discount factor | B19: =1/(1+$B$7)^B$12 -> 1 | C19: =1/(1+$B$7)^C$12 -> 0.92592593 | D19: =1/(1+$B$7)^D$12 -> 0.85733882 | E19: =1/(1+$B$7)^E$12 -> 0.79383224 | F19: =1/(1+$B$7)^F$12 -> 0.73502985 | G19: =1/(1+$B$7)^G$12 -> 0.6805832
A20: Present value | B20: =B17*B19 -> -650000 | C20: =C17*C19 -> 27777.778 | D20: =D17*D19 -> 222908.09 | E20: =E17*E19 -> 396916.12 | F20: =F17*F19 -> 499820.3 | G20: =G17*G19 -> 530854.89
A21: Cumulative present value | B21: =B20 -> -650000 | C21: =B21+C20 -> -622222.22 | D21: =C21+D20 -> -399314.13 | E21: =D21+E20 -> -2398.0084 | F21: =E21+F20 -> 497422.29 | G21: =F21+G20 -> 1028277.2
A22: Payback helper | B22: ="" | C22: =IF(AND(C18>=0,B18<0),B$12+(-B18)/C17,"") | D22: =IF(AND(D18>=0,C18<0),C$12+(-C18)/D17,"") | E22: =IF(AND(E18>=0,D18<0),D$12+(-D18)/E17,"") -> 2.72 | F22: =IF(AND(F18>=0,E18<0),E$12+(-E18)/F17,"") | G22: =IF(AND(G18>=0,F18<0),F$12+(-F18)/G17,"")
A25: RESULTS
A26: Net present value (NPV) | B26: =SUM(B20:G20) -> 1028277.2
A27: Internal rate of return (IRR) | B27: =IFERROR(IRR(B17:G17),"n/a") -> 0.4051949
A28: ROI (5-year net cash / investment) | B28: =SUM(B17:G17)/$B$5 -> 2.4615385
A29: Payback period (years) | B29: =IF(COUNT(C22:G22)=0,"> 5",MIN(C22:G22)) -> 2.72
A32: SENSITIVITY — NPV by revenue factor (rows) and discount rate (columns)
A33: Revenue factor \ Discount rate | B33: 0.06 | C33: 0.08 | D33: 0.1 | E33: 0.12
A34: 0.5 | B34: =-$B$5+SUMPRODUCT(($C$13:$G$13*$A34-$B$6)/(1+B$33)^$C$12:$G$12) -> -2243.9929 | C34: =-$B$5+SUMPRODUCT(($C$13:$G$13*$A34-$B$6)/(1+C$33)^$C$12:$G$12) -> -50424.01 | D34: =-$B$5+SUMPRODUCT(($C$13:$G$13*$A34-$B$6)/(1+D$33)^$C$12:$G$12) -> -94160.235 | E34: =-$B$5+SUMPRODUCT(($C$13:$G$13*$A34-$B$6)/(1+E$33)^$C$12:$G$12) -> -133940.83
A35: 0.75 | B35: =-$B$5+SUMPRODUCT(($C$13:$G$13*$A35-$B$6)/(1+B$33)^$C$12:$G$12) -> 574375.84 | C35: =-$B$5+SUMPRODUCT(($C$13:$G$13*$A35-$B$6)/(1+C$33)^$C$12:$G$12) -> 488926.59 | D35: =-$B$5+SUMPRODUCT(($C$13:$G$13*$A35-$B$6)/(1+D$33)^$C$12:$G$12) -> 411206.85 | E35: =-$B$5+SUMPRODUCT(($C$13:$G$13*$A35-$B$6)/(1+E$33)^$C$12:$G$12) -> 340375.33
A36: 1 | B36: =-$B$5+SUMPRODUCT(($C$13:$G$13*$A36-$B$6)/(1+B$33)^$C$12:$G$12) -> 1150995.7 | C36: =-$B$5+SUMPRODUCT(($C$13:$G$13*$A36-$B$6)/(1+C$33)^$C$12:$G$12) -> 1028277.2 | D36: =-$B$5+SUMPRODUCT(($C$13:$G$13*$A36-$B$6)/(1+D$33)^$C$12:$G$12) -> 916573.94 | E36: =-$B$5+SUMPRODUCT(($C$13:$G$13*$A36-$B$6)/(1+E$33)^$C$12:$G$12) -> 814691.49
A37: 1.25 | B37: =-$B$5+SUMPRODUCT(($C$13:$G$13*$A37-$B$6)/(1+B$33)^$C$12:$G$12) -> 1727615.5 | C37: =-$B$5+SUMPRODUCT(($C$13:$G$13*$A37-$B$6)/(1+C$33)^$C$12:$G$12) -> 1567627.8 | D37: =-$B$5+SUMPRODUCT(($C$13:$G$13*$A37-$B$6)/(1+D$33)^$C$12:$G$12) -> 1421941 | E37: =-$B$5+SUMPRODUCT(($C$13:$G$13*$A37-$B$6)/(1+E$33)^$C$12:$G$12) -> 1289007.6
A38: 1.5 | B38: =-$B$5+SUMPRODUCT(($C$13:$G$13*$A38-$B$6)/(1+B$33)^$C$12:$G$12) -> 2304235.3 | C38: =-$B$5+SUMPRODUCT(($C$13:$G$13*$A38-$B$6)/(1+C$33)^$C$12:$G$12) -> 2106978.4 | D38: =-$B$5+SUMPRODUCT(($C$13:$G$13*$A38-$B$6)/(1+D$33)^$C$12:$G$12) -> 1927308.1 | E38: =-$B$5+SUMPRODUCT(($C$13:$G$13*$A38-$B$6)/(1+E$33)^$C$12:$G$12) -> 1763323.8

Sheet Planning_Forecast
A1: FY2026 PLANNING & FORECAST — BUDGET VS. ACTUAL / OUTLOOK
A2: =HYPERLINK("#'Dashboard'!A1","◀ Back to Dashboard") -> ◀ Back to Dashboard | C2: Actuals through September 2026; October–December are forecast.
A5: Month | B5: Type | C5: Budget Revenue | D5: Actual / Forecast Revenue | E5: Variance | F5: Variance % | G5: Cumulative Budget | H5: Cumulative Outlook | I5: Profit | J5: Profit Margin % | K5: Billable Hours
A6: January | B6: =IF(COUNTIFS(Monthly_Data!$B$3:$B$146,2026,Monthly_Data!$C$3:$C$146,1,Monthly_Data!$F$3:$F$146,"Actual")>0,"Actual","Forecast") -> Actual | C6: =SUMIFS(Monthly_Data!$L$3:$L$146,Monthly_Data!$B$3:$B$146,2026,Monthly_Data!$C$3:$C$146,1) -> 4804600 | D6: =SUMIFS(Monthly_Data!$K$3:$K$146,Monthly_Data!$B$3:$B$146,2026,Monthly_Data!$C$3:$C$146,1) -> 4936880 | E6: =D6-C6 -> 132280 | F6: =IFERROR(E6/C6,0) -> 0.027531949 | G6: =C6 -> 4804600 | H6: =D6 -> 4936880 | I6: =SUMIFS(Monthly_Data!$S$3:$S$146,Monthly_Data!$B$3:$B$146,2026,Monthly_Data!$C$3:$C$146,1) -> 991720 | J6: =IFERROR(I6/D6,0) -> 0.20087991 | K6: =SUMIFS(Monthly_Data!$I$3:$I$146,Monthly_Data!$B$3:$B$146,2026,Monthly_Data!$C$3:$C$146,1) -> 15472
A7: February | B7: =IF(COUNTIFS(Monthly_Data!$B$3:$B$146,2026,Monthly_Data!$C$3:$C$146,2,Monthly_Data!$F$3:$F$146,"Actual")>0,"Actual","Forecast") -> Actual | C7: =SUMIFS(Monthly_Data!$L$3:$L$146,Monthly_Data!$B$3:$B$146,2026,Monthly_Data!$C$3:$C$146,2) -> 5209100 | D7: =SUMIFS(Monthly_Data!$K$3:$K$146,Monthly_Data!$B$3:$B$146,2026,Monthly_Data!$C$3:$C$146,2) -> 5175860 | E7: =D7-C7 -> -33240 | F7: =IFERROR(E7/C7,0) -> -0.0063811407 | G7: =G6+C7 -> 10013700 | H7: =H6+D7 -> 10112740 | I7: =SUMIFS(Monthly_Data!$S$3:$S$146,Monthly_Data!$B$3:$B$146,2026,Monthly_Data!$C$3:$C$146,2) -> 1160960 | J7: =IFERROR(I7/D7,0) -> 0.22430282 | K7: =SUMIFS(Monthly_Data!$I$3:$I$146,Monthly_Data!$B$3:$B$146,2026,Monthly_Data!$C$3:$C$146,2) -> 16611
A8: March | B8: =IF(COUNTIFS(Monthly_Data!$B$3:$B$146,2026,Monthly_Data!$C$3:$C$146,3,Monthly_Data!$F$3:$F$146,"Actual")>0,"Actual","Forecast") -> Actual | C8: =SUMIFS(Monthly_Data!$L$3:$L$146,Monthly_Data!$B$3:$B$146,2026,Monthly_Data!$C$3:$C$146,3) -> 6193600 | D8: =SUMIFS(Monthly_Data!$K$3:$K$146,Monthly_Data!$B$3:$B$146,2026,Monthly_Data!$C$3:$C$146,3) -> 6125060 | E8: =D8-C8 -> -68540 | F8: =IFERROR(E8/C8,0) -> -0.011066262 | G8: =G7+C8 -> 16207300 | H8: =H7+D8 -> 16237800 | I8: =SUMIFS(Monthly_Data!$S$3:$S$146,Monthly_Data!$B$3:$B$146,2026,Monthly_Data!$C$3:$C$146,3) -> 1930170 | J8: =IFERROR(I8/D8,0) -> 0.31512671 | K8: =SUMIFS(Monthly_Data!$I$3:$I$146,Monthly_Data!$B$3:$B$146,2026,Monthly_Data!$C$3:$C$146,3) -> 19269
A9: April | B9: =IF(COUNTIFS(Monthly_Data!$B$3:$B$146,2026,Monthly_Data!$C$3:$C$146,4,Monthly_Data!$F$3:$F$146,"Actual")>0,"Actual","Forecast") -> Actual | C9: =SUMIFS(Monthly_Data!$L$3:$L$146,Monthly_Data!$B$3:$B$146,2026,Monthly_Data!$C$3:$C$146,4) -> 5507900 | D9: =SUMIFS(Monthly_Data!$K$3:$K$146,Monthly_Data!$B$3:$B$146,2026,Monthly_Data!$C$3:$C$146,4) -> 5447210 | E9: =D9-C9 -> -60690 | F9: =IFERROR(E9/C9,0) -> -0.011018719 | G9: =G8+C9 -> 21715200 | H9: =H8+D9 -> 21685010 | I9: =SUMIFS(Monthly_Data!$S$3:$S$146,Monthly_Data!$B$3:$B$146,2026,Monthly_Data!$C$3:$C$146,4) -> 1355140 | J9: =IFERROR(I9/D9,0) -> 0.2487769 | K9: =SUMIFS(Monthly_Data!$I$3:$I$146,Monthly_Data!$B$3:$B$146,2026,Monthly_Data!$C$3:$C$146,4) -> 16945
A10: May | B10: =IF(COUNTIFS(Monthly_Data!$B$3:$B$146,2026,Monthly_Data!$C$3:$C$146,5,Monthly_Data!$F$3:$F$146,"Actual")>0,"Actual","Forecast") -> Actual | C10: =SUMIFS(Monthly_Data!$L$3:$L$146,Monthly_Data!$B$3:$B$146,2026,Monthly_Data!$C$3:$C$146,5) -> 5469900 | D10: =SUMIFS(Monthly_Data!$K$3:$K$146,Monthly_Data!$B$3:$B$146,2026,Monthly_Data!$C$3:$C$146,5) -> 5642410 | E10: =D10-C10 -> 172510 | F10: =IFERROR(E10/C10,0) -> 0.031538054 | G10: =G9+C10 -> 27185100 | H10: =H9+D10 -> 27327420 | I10: =SUMIFS(Monthly_Data!$S$3:$S$146,Monthly_Data!$B$3:$B$146,2026,Monthly_Data!$C$3:$C$146,5) -> 1560020 | J10: =IFERROR(I10/D10,0) -> 0.27648115 | K10: =SUMIFS(Monthly_Data!$I$3:$I$146,Monthly_Data!$B$3:$B$146,2026,Monthly_Data!$C$3:$C$146,5) -> 17657
A11: June | B11: =IF(COUNTIFS(Monthly_Data!$B$3:$B$146,2026,Monthly_Data!$C$3:$C$146,6,Monthly_Data!$F$3:$F$146,"Actual")>0,"Actual","Forecast") -> Actual | C11: =SUMIFS(Monthly_Data!$L$3:$L$146,Monthly_Data!$B$3:$B$146,2026,Monthly_Data!$C$3:$C$146,6) -> 6091100 | D11: =SUMIFS(Monthly_Data!$K$3:$K$146,Monthly_Data!$B$3:$B$146,2026,Monthly_Data!$C$3:$C$146,6) -> 6127590 | E11: =D11-C11 -> 36490 | F11: =IFERROR(E11/C11,0) -> 0.0059907078 | G11: =G10+C11 -> 33276200 | H11: =H10+D11 -> 33455010 | I11: =SUMIFS(Monthly_Data!$S$3:$S$146,Monthly_Data!$B$3:$B$146,2026,Monthly_Data!$C$3:$C$146,6) -> 1867840 | J11: =IFERROR(I11/D11,0) -> 0.30482457 | K11: =SUMIFS(Monthly_Data!$I$3:$I$146,Monthly_Data!$B$3:$B$146,2026,Monthly_Data!$C$3:$C$146,6) -> 19105
A12: July | B12: =IF(COUNTIFS(Monthly_Data!$B$3:$B$146,2026,Monthly_Data!$C$3:$C$146,7,Monthly_Data!$F$3:$F$146,"Actual")>0,"Actual","Forecast") -> Actual | C12: =SUMIFS(Monthly_Data!$L$3:$L$146,Monthly_Data!$B$3:$B$146,2026,Monthly_Data!$C$3:$C$146,7) -> 5612700 | D12: =SUMIFS(Monthly_Data!$K$3:$K$146,Monthly_Data!$B$3:$B$146,2026,Monthly_Data!$C$3:$C$146,7) -> 5594890 | E12: =D12-C12 -> -17810 | F12: =IFERROR(E12/C12,0) -> -0.0031731609 | G12: =G11+C12 -> 38888900 | H12: =H11+D12 -> 39049900 | I12: =SUMIFS(Monthly_Data!$S$3:$S$146,Monthly_Data!$B$3:$B$146,2026,Monthly_Data!$C$3:$C$146,7) -> 1453400 | J12: =IFERROR(I12/D12,0) -> 0.25977276 | K12: =SUMIFS(Monthly_Data!$I$3:$I$146,Monthly_Data!$B$3:$B$146,2026,Monthly_Data!$C$3:$C$146,7) -> 17850
A13: August | B13: =IF(COUNTIFS(Monthly_Data!$B$3:$B$146,2026,Monthly_Data!$C$3:$C$146,8,Monthly_Data!$F$3:$F$146,"Actual")>0,"Actual","Forecast") -> Actual | C13: =SUMIFS(Monthly_Data!$L$3:$L$146,Monthly_Data!$B$3:$B$146,2026,Monthly_Data!$C$3:$C$146,8) -> 4597800 | D13: =SUMIFS(Monthly_Data!$K$3:$K$146,Monthly_Data!$B$3:$B$146,2026,Monthly_Data!$C$3:$C$146,8) -> 4595840 | E13: =D13-C13 -> -1960 | F13: =IFERROR(E13/C13,0) -> -0.00042629083 | G13: =G12+C13 -> 43486700 | H13: =H12+D13 -> 43645740 | I13: =SUMIFS(Monthly_Data!$S$3:$S$146,Monthly_Data!$B$3:$B$146,2026,Monthly_Data!$C$3:$C$146,8) -> 635870 | J13: =IFERROR(I13/D13,0) -> 0.13835773 | K13: =SUMIFS(Monthly_Data!$I$3:$I$146,Monthly_Data!$B$3:$B$146,2026,Monthly_Data!$C$3:$C$146,8) -> 14502
A14: September | B14: =IF(COUNTIFS(Monthly_Data!$B$3:$B$146,2026,Monthly_Data!$C$3:$C$146,9,Monthly_Data!$F$3:$F$146,"Actual")>0,"Actual","Forecast") -> Actual | C14: =SUMIFS(Monthly_Data!$L$3:$L$146,Monthly_Data!$B$3:$B$146,2026,Monthly_Data!$C$3:$C$146,9) -> 6313200 | D14: =SUMIFS(Monthly_Data!$K$3:$K$146,Monthly_Data!$B$3:$B$146,2026,Monthly_Data!$C$3:$C$146,9) -> 6205960 | E14: =D14-C14 -> -107240 | F14: =IFERROR(E14/C14,0) -> -0.016986631 | G14: =G13+C14 -> 49799900 | H14: =H13+D14 -> 49851700 | I14: =SUMIFS(Monthly_Data!$S$3:$S$146,Monthly_Data!$B$3:$B$146,2026,Monthly_Data!$C$3:$C$146,9) -> 1927550 | J14: =IFERROR(I14/D14,0) -> 0.31059659 | K14: =SUMIFS(Monthly_Data!$I$3:$I$146,Monthly_Data!$B$3:$B$146,2026,Monthly_Data!$C$3:$C$146,9) -> 19415
A15: October | B15: =IF(COUNTIFS(Monthly_Data!$B$3:$B$146,2026,Monthly_Data!$C$3:$C$146,10,Monthly_Data!$F$3:$F$146,"Actual")>0,"Actual","Forecast") -> Forecast | C15: =SUMIFS(Monthly_Data!$L$3:$L$146,Monthly_Data!$B$3:$B$146,2026,Monthly_Data!$C$3:$C$146,10) -> 6407700 | D15: =SUMIFS(Monthly_Data!$K$3:$K$146,Monthly_Data!$B$3:$B$146,2026,Monthly_Data!$C$3:$C$146,10) -> 6338160 | E15: =D15-C15 -> -69540 | F15: =IFERROR(E15/C15,0) -> -0.010852568 | G15: =G14+C15 -> 56207600 | H15: =H14+D15 -> 56189860 | I15: =SUMIFS(Monthly_Data!$S$3:$S$146,Monthly_Data!$B$3:$B$146,2026,Monthly_Data!$C$3:$C$146,10) -> 1916370 | J15: =IFERROR(I15/D15,0) -> 0.30235431 | K15: =SUMIFS(Monthly_Data!$I$3:$I$146,Monthly_Data!$B$3:$B$146,2026,Monthly_Data!$C$3:$C$146,10) -> 20078
A16: November | B16: =IF(COUNTIFS(Monthly_Data!$B$3:$B$146,2026,Monthly_Data!$C$3:$C$146,11,Monthly_Data!$F$3:$F$146,"Actual")>0,"Actual","Forecast") -> Forecast | C16: =SUMIFS(Monthly_Data!$L$3:$L$146,Monthly_Data!$B$3:$B$146,2026,Monthly_Data!$C$3:$C$146,11) -> 6597500 | D16: =SUMIFS(Monthly_Data!$K$3:$K$146,Monthly_Data!$B$3:$B$146,2026,Monthly_Data!$C$3:$C$146,11) -> 6706020 | E16: =D16-C16 -> 108520 | F16: =IFERROR(E16/C16,0) -> 0.016448655 | G16: =G15+C16 -> 62805100 | H16: =H15+D16 -> 62895880 | I16: =SUMIFS(Monthly_Data!$S$3:$S$146,Monthly_Data!$B$3:$B$146,2026,Monthly_Data!$C$3:$C$146,11) -> 2357250 | J16: =IFERROR(I16/D16,0) -> 0.35151252 | K16: =SUMIFS(Monthly_Data!$I$3:$I$146,Monthly_Data!$B$3:$B$146,2026,Monthly_Data!$C$3:$C$146,11) -> 20949
A17: December | B17: =IF(COUNTIFS(Monthly_Data!$B$3:$B$146,2026,Monthly_Data!$C$3:$C$146,12,Monthly_Data!$F$3:$F$146,"Actual")>0,"Actual","Forecast") -> Forecast | C17: =SUMIFS(Monthly_Data!$L$3:$L$146,Monthly_Data!$B$3:$B$146,2026,Monthly_Data!$C$3:$C$146,12) -> 5394300 | D17: =SUMIFS(Monthly_Data!$K$3:$K$146,Monthly_Data!$B$3:$B$146,2026,Monthly_Data!$C$3:$C$146,12) -> 5379740 | E17: =D17-C17 -> -14560 | F17: =IFERROR(E17/C17,0) -> -0.0026991454 | G17: =G16+C17 -> 68199400 | H17: =H16+D17 -> 68275620 | I17: =SUMIFS(Monthly_Data!$S$3:$S$146,Monthly_Data!$B$3:$B$146,2026,Monthly_Data!$C$3:$C$146,12) -> 1218800 | J17: =IFERROR(I17/D17,0) -> 0.2265537 | K17: =SUMIFS(Monthly_Data!$I$3:$I$146,Monthly_Data!$B$3:$B$146,2026,Monthly_Data!$C$3:$C$146,12) -> 16781
A18: FY2026 | C18: =SUM(C6:C17) -> 68199400 | D18: =SUM(D6:D17) -> 68275620 | E18: =SUM(E6:E17) -> 76220 | F18: =IFERROR(E18/C18,0) -> 0.0011176051 | I18: =SUM(I6:I17) -> 18375090 | J18: =IFERROR(I18/D18,0) -> 0.26913106 | K18: =SUM(K6:K17) -> 214634
A21: FULL-YEAR OUTLOOK
A22: FY budget revenue | B22: =C18 -> 68199400
A23: YTD actual revenue | B23: =SUMIFS(D6:D17,B6:B17,"Actual") -> 49851700
A24: Remaining forecast | B24: =SUMIFS(D6:D17,B6:B17,"Forecast") -> 18423920
A25: FY outlook | B25: =B23+B24 -> 68275620
A26: Gap to budget | B26: =B25-B22 -> 76220
A27: Gap to budget % | B27: =IFERROR(B26/B22,0) -> 0.0011176051
A28: FY outlook profit | B28: =I18 -> 18375090
A29: FY outlook margin | B29: =J18 -> 0.26913106

Sheet Action_Tracker
A1: BUSINESS PARTNERING — FINDINGS & AGREED ACTIONS
A2: =HYPERLINK("#'Dashboard'!A1","◀ Back to Dashboard") -> ◀ Back to Dashboard
A4: # | B4: Practice Area | C4: Finding | D4: Option for Action | E4: Owner | F4: Due | G4: Status | H4: Expected Impact (EUR p.a.)
A5: 1 | B5: Tech & Data | C5: Lowest utilization of all teams | D5: Rebalance staffing; shift internal project work to quieter months | E5: Head of Tech & Data | F5: 46341 | G5: In progress | H5: 180000
A6: 2 | B6: Tech & Data | C6: Highest share of written-off hours | D6: Introduce interim billing and scope checkpoints on fixed-fee mandates | E6: Head of Tech & Data | F6: 46357 | G6: Open | H6: 150000
A7: 3 | B7: M&A / Transactions | C7: Largest gap between list rate and realized rate | D7: Review discount approvals; define floor rates for repeat clients | E7: Partner M&A | F7: 46356 | G7: Open | H7: 320000
A8: 4 | B8: Tax | C8: Realization below firm average | D8: Monthly review of unbilled services older than 60 days | E8: Head of Tax | F8: 46326 | G8: In progress | H8: 90000
A9: 5 | B9: Regulatory & Fin. Services | C9: Utilization below target in summer months | D9: Align holiday planning and mandate pipeline | E9: Partner Regulatory | F9: 46418 | G9: Open | H9: 60000
A10: 6 | B10: Private Equity & VC | C10: Rate card unchanged for two years | D10: Prepare rate-card update proposal with client-segment view | E10: Managing Partner | F10: 46371 | G10: Done | H10: 410000
A13: Total expected impact | H13: =SUM(H5:H10) -> 1210000
A14: thereof implemented (Done) | H14: =SUMIFS(H5:H10,G5:G10,"Done") -> 410000
A15: Implementation rate | H15: =IFERROR(H14/H13,0) -> 0.33884298

Sheet BI_Requirements
A1: REPORTING — POWER BI DASHBOARD REQUIREMENTS (specification example)
A2: =HYPERLINK("#'Dashboard'!A1","◀ Back to Dashboard") -> ◀ Back to Dashboard
A4: KPI / Visual | B4: Definition | C4: Source | D4: Refresh | E4: Decision supported | F4: Audience | G4: Priority
A5: Revenue vs. budget | B5: Invoiced fees vs. budget, by month and practice area, incl. forecast months | C5: Billing system, planning file | D5: Daily | E5: Early steering of budget gaps | F5: Management, partners | G5: High
A6: Utilization | B6: Billable hours / available hours (FTE-adjusted) | C6: Time recording, HR (FTE) | D6: Daily | E6: Staffing and capacity decisions | F6: Practice heads | G6: High
A7: Realization | B7: Invoiced hours / billable hours; write-offs by team and client | C7: Time recording, billing | D7: Weekly | E7: Billing discipline, scope management | F7: Practice heads, controlling | G7: High
A8: Realized rate | B8: Revenue / invoiced hours vs. list rate | C8: Billing, rate card | D8: Weekly | E8: Pricing decisions, discount approvals | F8: Partners | G8: High
A9: Unbilled services (WIP) | B9: Value of recorded, not yet invoiced time, aged by months | C9: Time recording, billing | D9: Daily | E9: Cash conversion, invoicing priorities | F9: Partners, accounting | G9: High
A10: Profitability | B10: Revenue less personnel and other costs, margin by team | C10: Accounting, cost allocation | D10: Monthly | E10: Investment and resourcing decisions | F10: Management | G10: Medium
A11: Revenue per FTE | B11: Revenue / average FTE | C11: Billing, HR | D11: Monthly | E11: Productivity benchmarking | F11: Management | G11: Medium
A12: Forecast accuracy | B12: Forecast vs. actual by quarter | C12: Planning file, billing | D12: Quarterly | E12: Quality of planning process | F12: Controlling | G12: Medium
A13: Business-case tracker | B13: NPV, IRR, payback of approved investments vs. plan | C13: Business-case model | D13: Quarterly | E13: Investment follow-up | F13: Management | G13: Low
A16: Data model note: one fact table (monthly hours, revenue, cost by practice area) with dimension tables for date, practice area and rate card.

Sheet Monthly_Data
A1: MONTHLY DATA — BY PRACTICE AREA (illustrative sample data, EUR)
A2: Month | B2: Year | C2: Month# | D2: Month Name | E2: Practice Area | F2: Type | G2: FTE | H2: Available Hours | I2: Billable Hours | J2: Invoiced Hours | K2: Revenue | L2: Budget Revenue | M2: Personnel Cost | N2: Other Cost | O2: Unbilled WIP (month-end) | P2: List Rate (EUR/h) | Q2: Value at List Rate | R2: Write-off Value | S2: Profit
A3: 45658 | B3: 2025 | C3: 1 | D3: January | E3: Private Equity & VC | F3: Actual | G3: 37.2 | H3: 5285 | I3: 3349 | J3: 3165 | K3: 1157900 | L3: 1159400 | M3: 583100 | N3: 232830 | O3: 612700 | P3: =INDEX(Pricing_Analysis!$B$6:$B$11,MATCH(E3,Pricing_Analysis!$A$6:$A$11,0)) -> 390 | Q3: =I3*P3 -> 1306110 | R3: =(I3-J3)*P3 -> 71760 | S3: =K3-M3-N3 -> 341970
A4: 45658 | B4: 2025 | C4: 1 | D4: January | E4: Funds & Asset Mgmt | F4: Actual | G4: 29.4 | H4: 4177 | I4: 2631 | J4: 2359 | K4: 802160 | L4: 749600 | M4: 473910 | N4: 185790 | O4: 292500 | P4: =INDEX(Pricing_Analysis!$B$6:$B$11,MATCH(E4,Pricing_Analysis!$A$6:$A$11,0)) -> 370 | Q4: =I4*P4 -> 973470 | R4: =(I4-J4)*P4 -> 100640 | S4: =K4-M4-N4 -> 142460
A5: 45658 | B5: 2025 | C5: 1 | D5: January | E5: Tax | F5: Actual | G5: 25.7 | H5: 3651 | I5: 2269 | J5: 2048 | K5: 645060 | L5: 609700 | M5: 373420 | N5: 143010 | O5: 239200 | P5: =INDEX(Pricing_Analysis!$B$6:$B$11,MATCH(E5,Pricing_Analysis!$A$6:$A$11,0)) -> 340 | Q5: =I5*P5 -> 771460 | R5: =(I5-J5)*P5 -> 75140 | S5: =K5-M5-N5 -> 128630
A6: 45658 | B6: 2025 | C6: 1 | D6: January | E6: M&A / Transactions | F6: Actual | G6: 40.9 | H6: 5811 | I6: 3668 | J6: 3243 | K6: 1167540 | L6: 1156400 | M6: 661960 | N6: 258200 | O6: 670300 | P6: =INDEX(Pricing_Analysis!$B$6:$B$11,MATCH(E6,Pricing_Analysis!$A$6:$A$11,0)) -> 410 | Q6: =I6*P6 -> 1503880 | R6: =(I6-J6)*P6 -> 174250 | S6: =K6-M6-N6 -> 247380
A7: 45658 | B7: 2025 | C7: 1 | D7: January | E7: Regulatory & Fin. Services | F7: Actual | G7: 21.2 | H7: 3012 | I7: 1763 | J7: 1645 | K7: 547390 | L7: 591000 | M7: 349620 | N7: 131600 | O7: 327200 | P7: =INDEX(Pricing_Analysis!$B$6:$B$11,MATCH(E7,Pricing_Analysis!$A$6:$A$11,0)) -> 355 | Q7: =I7*P7 -> 625865 | R7: =(I7-J7)*P7 -> 41890 | S7: =K7-M7-N7 -> 66170
A8: 45658 | B8: 2025 | C8: 1 | D8: January | E8: Tech & Data | F8: Actual | G8: 13.1 | H8: 1861 | I8: 1010 | J8: 865 | K8: 253060 | L8: 263800 | M8: 200440 | N8: 60940 | O8: 122800 | P8: =INDEX(Pricing_Analysis!$B$6:$B$11,MATCH(E8,Pricing_Analysis!$A$6:$A$11,0)) -> 330 | Q8: =I8*P8 -> 333300 | R8: =(I8-J8)*P8 -> 47850 | S8: =K8-M8-N8 -> -8320
A9: 45689 | B9: 2025 | C9: 2 | D9: February | E9: Private Equity & VC | F9: Actual | G9: 37.9 | H9: 5385 | I9: 3705 | J9: 3342 | K9: 1203840 | L9: 1282900 | M9: 585180 | N9: 299540 | O9: 588800 | P9: =INDEX(Pricing_Analysis!$B$6:$B$11,MATCH(E9,Pricing_Analysis!$A$6:$A$11,0)) -> 390 | Q9: =I9*P9 -> 1444950 | R9: =(I9-J9)*P9 -> 141570 | S9: =K9-M9-N9 -> 319120
A10: 45689 | B10: 2025 | C10: 2 | D10: February | E10: Funds & Asset Mgmt | F10: Actual | G10: 29 | H10: 4120 | I10: 2696 | J10: 2502 | K10: 849050 | L10: 793000 | M10: 439790 | N10: 210430 | O10: 522400 | P10: =INDEX(Pricing_Analysis!$B$6:$B$11,MATCH(E10,Pricing_Analysis!$A$6:$A$11,0)) -> 370 | Q10: =I10*P10 -> 997520 | R10: =(I10-J10)*P10 -> 71780 | S10: =K10-M10-N10 -> 198830
A11: 45689 | B11: 2025 | C11: 2 | D11: February | E11: Tax | F11: Actual | G11: 25 | H11: 3552 | I11: 2171 | J11: 1905 | K11: 580150 | L11: 607700 | M11: 371380 | N11: 129700 | O11: 293900 | P11: =INDEX(Pricing_Analysis!$B$6:$B$11,MATCH(E11,Pricing_Analysis!$A$6:$A$11,0)) -> 340 | Q11: =I11*P11 -> 738140 | R11: =(I11-J11)*P11 -> 90440 | S11: =K11-M11-N11 -> 79070
A12: 45689 | B12: 2025 | C12: 2 | D12: February | E12: M&A / Transactions | F12: Actual | G12: 41.1 | H12: 5839 | I12: 4086 | J12: 3631 | K12: 1321360 | L12: 1240300 | M12: 630540 | N12: 267930 | O12: 587200 | P12: =INDEX(Pricing_Analysis!$B$6:$B$11,MATCH(E12,Pricing_Analysis!$A$6:$A$11,0)) -> 410 | Q12: =I12*P12 -> 1675260 | R12: =(I12-J12)*P12 -> 186550 | S12: =K12-M12-N12 -> 422890
A13: 45689 | B13: 2025 | C13: 2 | D13: February | E13: Regulatory & Fin. Services | F13: Actual | G13: 21.9 | H13: 3112 | I13: 1950 | J13: 1806 | K13: 623140 | L13: 594300 | M13: 334820 | N13: 150340 | O13: 358100 | P13: =INDEX(Pricing_Analysis!$B$6:$B$11,MATCH(E13,Pricing_Analysis!$A$6:$A$11,0)) -> 355 | Q13: =I13*P13 -> 692250 | R13: =(I13-J13)*P13 -> 51120 | S13: =K13-M13-N13 -> 137980
A14: 45689 | B14: 2025 | C14: 2 | D14: February | E14: Tech & Data | F14: Actual | G14: 13 | H14: 1847 | I14: 1141 | J14: 973 | K14: 287950 | L14: 300500 | M14: 197050 | N14: 59830 | O14: 108200 | P14: =INDEX(Pricing_Analysis!$B$6:$B$11,MATCH(E14,Pricing_Analysis!$A$6:$A$11,0)) -> 330 | Q14: =I14*P14 -> 376530 | R14: =(I14-J14)*P14 -> 55440 | S14: =K14-M14-N14 -> 31070
... A146: 46357 | B146: 2026 | C146: 12 | D146: December | E146: Tech & Data | F146: Forecast | G146: 16 | H146: 2084 | I146: 1294 | J146: 1120 | K146: 347080 | L146: 357300 | M146: 256120 | N146: 85760 | O146: 142600 | P146: =INDEX(Pricing_Analysis!$B$6:$B$11,MATCH(E146,Pricing_Analysis!$A$6:$A$11,0)) -> 330 | Q146: =I146*P146 -> 427020 | R146: =(I146-J146)*P146 -> 57420 | S146: =K146-M146-N146 -> 5200

Sheet Calc_Engine
A1: CALC ENGINE (hidden) — Dashboard!D5 (year), Dashboard!H5 (practice area)
A3: KPI | B3: Value
A4: Revenue | B4: =SUMIFS(Monthly_Data!$K$3:$K$146,Monthly_Data!$B$3:$B$146,Dashboard!$D$5,Monthly_Data!$E$3:$E$146,IF(Dashboard!$H$5="All","*",Dashboard!$H$5)) -> 68275620
A5: Budget | B5: =SUMIFS(Monthly_Data!$L$3:$L$146,Monthly_Data!$B$3:$B$146,Dashboard!$D$5,Monthly_Data!$E$3:$E$146,IF(Dashboard!$H$5="All","*",Dashboard!$H$5)) -> 68199400
A6: Revenue vs budget | B6: =IFERROR((B4-B5)/B5,0) -> 0.0011176051
A7: Profit | B7: =SUMIFS(Monthly_Data!$S$3:$S$146,Monthly_Data!$B$3:$B$146,Dashboard!$D$5,Monthly_Data!$E$3:$E$146,IF(Dashboard!$H$5="All","*",Dashboard!$H$5)) -> 18375090
A8: Profit margin | B8: =IFERROR(B7/B4,0) -> 0.26913106
A9: Available hours | B9: =SUMIFS(Monthly_Data!$H$3:$H$146,Monthly_Data!$B$3:$B$146,Dashboard!$D$5,Monthly_Data!$E$3:$E$146,IF(Dashboard!$H$5="All","*",Dashboard!$H$5)) -> 313712
A10: Billable hours | B10: =SUMIFS(Monthly_Data!$I$3:$I$146,Monthly_Data!$B$3:$B$146,Dashboard!$D$5,Monthly_Data!$E$3:$E$146,IF(Dashboard!$H$5="All","*",Dashboard!$H$5)) -> 214634
A11: Invoiced hours | B11: =SUMIFS(Monthly_Data!$J$3:$J$146,Monthly_Data!$B$3:$B$146,Dashboard!$D$5,Monthly_Data!$E$3:$E$146,IF(Dashboard!$H$5="All","*",Dashboard!$H$5)) -> 195536
A12: Utilization | B12: =IFERROR(B10/B9,0) -> 0.68417529
A13: Realization | B13: =IFERROR(B11/B10,0) -> 0.91102062
A14: Realized rate | B14: =IFERROR(B4/B11,0) -> 349.17161
A15: Average FTE | B15: =SUMIFS(Monthly_Data!$G$3:$G$146,Monthly_Data!$B$3:$B$146,Dashboard!$D$5,Monthly_Data!$E$3:$E$146,IF(Dashboard!$H$5="All","*",Dashboard!$H$5))/12 -> 182.74167
A16: Revenue per FTE | B16: =IFERROR(B4/B15,0) -> 373618.24
A17: Last actual month | B17: =_xlfn.MAXIFS(Monthly_Data!$C$3:$C$146,Monthly_Data!$B$3:$B$146,Dashboard!$D$5,Monthly_Data!$F$3:$F$146,"Actual") -> 9
A18: Latest WIP | B18: =SUMIFS(Monthly_Data!$O$3:$O$146,Monthly_Data!$B$3:$B$146,Dashboard!$D$5,Monthly_Data!$C$3:$C$146,B17,Monthly_Data!$E$3:$E$146,IF(Dashboard!$H$5="All","*",Dashboard!$H$5)) -> 2869100
A19: Personnel cost | B19: =SUMIFS(Monthly_Data!$M$3:$M$146,Monthly_Data!$B$3:$B$146,Dashboard!$D$5,Monthly_Data!$E$3:$E$146,IF(Dashboard!$H$5="All","*",Dashboard!$H$5)) -> 34887000
A20: Other cost | B20: =SUMIFS(Monthly_Data!$N$3:$N$146,Monthly_Data!$B$3:$B$146,Dashboard!$D$5,Monthly_Data!$E$3:$E$146,IF(Dashboard!$H$5="All","*",Dashboard!$H$5)) -> 15013530
A21: Value at list rate | B21: =SUMIFS(Monthly_Data!$Q$3:$Q$146,Monthly_Data!$B$3:$B$146,Dashboard!$D$5,Monthly_Data!$E$3:$E$146,IF(Dashboard!$H$5="All","*",Dashboard!$H$5)) -> 80621575
A22: Write-off value | B22: =SUMIFS(Monthly_Data!$R$3:$R$146,Monthly_Data!$B$3:$B$146,Dashboard!$D$5,Monthly_Data!$E$3:$E$146,IF(Dashboard!$H$5="All","*",Dashboard!$H$5)) -> 7168410
A23: Rate discount | B23: =B21-B22-B4 -> 5177545
A26: Step | B26: Base | C26: Value
A27: List value | B27: 0 | C27: =B21 -> 80621575
A28: Write-offs | B28: =B21-B22 -> 73453165 | C28: =B22 -> 7168410
A29: Rate discounts | B29: =B4 -> 68275620 | C29: =B23 -> 5177545
A30: Realized | B30: 0 | C30: =B4 -> 68275620
A33: Month | B33: Actual | C33: Forecast | D33: Budget | E33: Utilization | F33: Realization
A34: Jan | B34: =SUMIFS(Monthly_Data!$K$3:$K$146,Monthly_Data!$B$3:$B$146,Dashboard!$D$5,Monthly_Data!$E$3:$E$146,IF(Dashboard!$H$5="All","*",Dashboard!$H$5),Monthly_Data!$C$3:$C$146,1,Monthly_Data!$F$3:$F$146,"Actual") -> 4936880 | C34: =SUMIFS(Monthly_Data!$K$3:$K$146,Monthly_Data!$B$3:$B$146,Dashboard!$D$5,Monthly_Data!$E$3:$E$146,IF(Dashboard!$H$5="All","*",Dashboard!$H$5),Monthly_Data!$C$3:$C$146,1,Monthly_Data!$F$3:$F$146,"Forecast") -> 0 | D34: =SUMIFS(Monthly_Data!$L$3:$L$146,Monthly_Data!$B$3:$B$146,Dashboard!$D$5,Monthly_Data!$E$3:$E$146,IF(Dashboard!$H$5="All","*",Dashboard!$H$5),Monthly_Data!$C$3:$C$146,1) -> 4804600 | E34: =IFERROR(SUMIFS(Monthly_Data!$I$3:$I$146,Monthly_Data!$B$3:$B$146,Dashboard!$D$5,Monthly_Data!$E$3:$E$146,IF(Dashboard!$H$5="All","*",Dashboard!$H$5),Monthly_Data!$C$3:$C$146,1)/SUMIFS(Monthly_Data!$H$3:$H$146,Monthly_Data!$B$3:$B$146,Dashboard!$D$5,Monthly_Data!$E$3:$E$146,IF(Dashboard!$H$5="All","*",Dashboard!$H$5),Monthly_Data!$C$3:$C$146,1),0) -> 0.61178331 | F34: =IFERROR(SUMIFS(Monthly_Data!$J$3:$J$146,Monthly_Data!$B$3:$B$146,Dashboard!$D$5,Monthly_Data!$E$3:$E$146,IF(Dashboard!$H$5="All","*",Dashboard!$H$5),Monthly_Data!$C$3:$C$146,1)/SUMIFS(Monthly_Data!$I$3:$I$146,Monthly_Data!$B$3:$B$146,Dashboard!$D$5,Monthly_Data!$E$3:$E$146,IF(Dashboard!$H$5="All","*",Dashboard!$H$5),Monthly_Data!$C$3:$C$146,1),0) -> 0.9182394
A35: Feb | B35: =SUMIFS(Monthly_Data!$K$3:$K$146,Monthly_Data!$B$3:$B$146,Dashboard!$D$5,Monthly_Data!$E$3:$E$146,IF(Dashboard!$H$5="All","*",Dashboard!$H$5),Monthly_Data!$C$3:$C$146,2,Monthly_Data!$F$3:$F$146,"Actual") -> 5175860 | C35: =SUMIFS(Monthly_Data!$K$3:$K$146,Monthly_Data!$B$3:$B$146,Dashboard!$D$5,Monthly_Data!$E$3:$E$146,IF(Dashboard!$H$5="All","*",Dashboard!$H$5),Monthly_Data!$C$3:$C$146,2,Monthly_Data!$F$3:$F$146,"Forecast") -> 0 | D35: =SUMIFS(Monthly_Data!$L$3:$L$146,Monthly_Data!$B$3:$B$146,Dashboard!$D$5,Monthly_Data!$E$3:$E$146,IF(Dashboard!$H$5="All","*",Dashboard!$H$5),Monthly_Data!$C$3:$C$146,2) -> 5209100 | E35: =IFERROR(SUMIFS(Monthly_Data!$I$3:$I$146,Monthly_Data!$B$3:$B$146,Dashboard!$D$5,Monthly_Data!$E$3:$E$146,IF(Dashboard!$H$5="All","*",Dashboard!$H$5),Monthly_Data!$C$3:$C$146,2)/SUMIFS(Monthly_Data!$H$3:$H$146,Monthly_Data!$B$3:$B$146,Dashboard!$D$5,Monthly_Data!$E$3:$E$146,IF(Dashboard!$H$5="All","*",Dashboard!$H$5),Monthly_Data!$C$3:$C$146,2),0) -> 0.65425972 | F35: =IFERROR(SUMIFS(Monthly_Data!$J$3:$J$146,Monthly_Data!$B$3:$B$146,Dashboard!$D$5,Monthly_Data!$E$3:$E$146,IF(Dashboard!$H$5="All","*",Dashboard!$H$5),Monthly_Data!$C$3:$C$146,2)/SUMIFS(Monthly_Data!$I$3:$I$146,Monthly_Data!$B$3:$B$146,Dashboard!$D$5,Monthly_Data!$E$3:$E$146,IF(Dashboard!$H$5="All","*",Dashboard!$H$5),Monthly_Data!$C$3:$C$146,2),0) -> 0.90181205
A36: Mar | B36: =SUMIFS(Monthly_Data!$K$3:$K$146,Monthly_Data!$B$3:$B$146,Dashboard!$D$5,Monthly_Data!$E$3:$E$146,IF(Dashboard!$H$5="All","*",Dashboard!$H$5),Monthly_Data!$C$3:$C$146,3,Monthly_Data!$F$3:$F$146,"Actual") -> 6125060 | C36: =SUMIFS(Monthly_Data!$K$3:$K$146,Monthly_Data!$B$3:$B$146,Dashboard!$D$5,Monthly_Data!$E$3:$E$146,IF(Dashboard!$H$5="All","*",Dashboard!$H$5),Monthly_Data!$C$3:$C$146,3,Monthly_Data!$F$3:$F$146,"Forecast") -> 0 | D36: =SUMIFS(Monthly_Data!$L$3:$L$146,Monthly_Data!$B$3:$B$146,Dashboard!$D$5,Monthly_Data!$E$3:$E$146,IF(Dashboard!$H$5="All","*",Dashboard!$H$5),Monthly_Data!$C$3:$C$146,3) -> 6193600 | E36: =IFERROR(SUMIFS(Monthly_Data!$I$3:$I$146,Monthly_Data!$B$3:$B$146,Dashboard!$D$5,Monthly_Data!$E$3:$E$146,IF(Dashboard!$H$5="All","*",Dashboard!$H$5),Monthly_Data!$C$3:$C$146,3)/SUMIFS(Monthly_Data!$H$3:$H$146,Monthly_Data!$B$3:$B$146,Dashboard!$D$5,Monthly_Data!$E$3:$E$146,IF(Dashboard!$H$5="All","*",Dashboard!$H$5),Monthly_Data!$C$3:$C$146,3),0) -> 0.72130718 | F36: =IFERROR(SUMIFS(Monthly_Data!$J$3:$J$146,Monthly_Data!$B$3:$B$146,Dashboard!$D$5,Monthly_Data!$E$3:$E$146,IF(Dashboard!$H$5="All","*",Dashboard!$H$5),Monthly_Data!$C$3:$C$146,3)/SUMIFS(Monthly_Data!$I$3:$I$146,Monthly_Data!$B$3:$B$146,Dashboard!$D$5,Monthly_Data!$E$3:$E$146,IF(Dashboard!$H$5="All","*",Dashboard!$H$5),Monthly_Data!$C$3:$C$146,3),0) -> 0.90918055
A37: Apr | B37: =SUMIFS(Monthly_Data!$K$3:$K$146,Monthly_Data!$B$3:$B$146,Dashboard!$D$5,Monthly_Data!$E$3:$E$146,IF(Dashboard!$H$5="All","*",Dashboard!$H$5),Monthly_Data!$C$3:$C$146,4,Monthly_Data!$F$3:$F$146,"Actual") -> 5447210 | C37: =SUMIFS(Monthly_Data!$K$3:$K$146,Monthly_Data!$B$3:$B$146,Dashboard!$D$5,Monthly_Data!$E$3:$E$146,IF(Dashboard!$H$5="All","*",Dashboard!$H$5),Monthly_Data!$C$3:$C$146,4,Monthly_Data!$F$3:$F$146,"Forecast") -> 0 | D37: =SUMIFS(Monthly_Data!$L$3:$L$146,Monthly_Data!$B$3:$B$146,Dashboard!$D$5,Monthly_Data!$E$3:$E$146,IF(Dashboard!$H$5="All","*",Dashboard!$H$5),Monthly_Data!$C$3:$C$146,4) -> 5507900 | E37: =IFERROR(SUMIFS(Monthly_Data!$I$3:$I$146,Monthly_Data!$B$3:$B$146,Dashboard!$D$5,Monthly_Data!$E$3:$E$146,IF(Dashboard!$H$5="All","*",Dashboard!$H$5),Monthly_Data!$C$3:$C$146,4)/SUMIFS(Monthly_Data!$H$3:$H$146,Monthly_Data!$B$3:$B$146,Dashboard!$D$5,Monthly_Data!$E$3:$E$146,IF(Dashboard!$H$5="All","*",Dashboard!$H$5),Monthly_Data!$C$3:$C$146,4),0) -> 0.67553022 | F37: =IFERROR(SUMIFS(Monthly_Data!$J$3:$J$146,Monthly_Data!$B$3:$B$146,Dashboard!$D$5,Monthly_Data!$E$3:$E$146,IF(Dashboard!$H$5="All","*",Dashboard!$H$5),Monthly_Data!$C$3:$C$146,4)/SUMIFS(Monthly_Data!$I$3:$I$146,Monthly_Data!$B$3:$B$146,Dashboard!$D$5,Monthly_Data!$E$3:$E$146,IF(Dashboard!$H$5="All","*",Dashboard!$H$5),Monthly_Data!$C$3:$C$146,4),0) -> 0.91696666
A38: May | B38: =SUMIFS(Monthly_Data!$K$3:$K$146,Monthly_Data!$B$3:$B$146,Dashboard!$D$5,Monthly_Data!$E$3:$E$146,IF(Dashboard!$H$5="All","*",Dashboard!$H$5),Monthly_Data!$C$3:$C$146,5,Monthly_Data!$F$3:$F$146,"Actual") -> 5642410 | C38: =SUMIFS(Monthly_Data!$K$3:$K$146,Monthly_Data!$B$3:$B$146,Dashboard!$D$5,Monthly_Data!$E$3:$E$146,IF(Dashboard!$H$5="All","*",Dashboard!$H$5),Monthly_Data!$C$3:$C$146,5,Monthly_Data!$F$3:$F$146,"Forecast") -> 0 | D38: =SUMIFS(Monthly_Data!$L$3:$L$146,Monthly_Data!$B$3:$B$146,Dashboard!$D$5,Monthly_Data!$E$3:$E$146,IF(Dashboard!$H$5="All","*",Dashboard!$H$5),Monthly_Data!$C$3:$C$146,5) -> 5469900 | E38: =IFERROR(SUMIFS(Monthly_Data!$I$3:$I$146,Monthly_Data!$B$3:$B$146,Dashboard!$D$5,Monthly_Data!$E$3:$E$146,IF(Dashboard!$H$5="All","*",Dashboard!$H$5),Monthly_Data!$C$3:$C$146,5)/SUMIFS(Monthly_Data!$H$3:$H$146,Monthly_Data!$B$3:$B$146,Dashboard!$D$5,Monthly_Data!$E$3:$E$146,IF(Dashboard!$H$5="All","*",Dashboard!$H$5),Monthly_Data!$C$3:$C$146,5),0) -> 0.69229563 | F38: =IFERROR(SUMIFS(Monthly_Data!$J$3:$J$146,Monthly_Data!$B$3:$B$146,Dashboard!$D$5,Monthly_Data!$E$3:$E$146,IF(Dashboard!$H$5="All","*",Dashboard!$H$5),Monthly_Data!$C$3:$C$146,5)/SUMIFS(Monthly_Data!$I$3:$I$146,Monthly_Data!$B$3:$B$146,Dashboard!$D$5,Monthly_Data!$E$3:$E$146,IF(Dashboard!$H$5="All","*",Dashboard!$H$5),Monthly_Data!$C$3:$C$146,5),0) -> 0.91317891
A39: Jun | B39: =SUMIFS(Monthly_Data!$K$3:$K$146,Monthly_Data!$B$3:$B$146,Dashboard!$D$5,Monthly_Data!$E$3:$E$146,IF(Dashboard!$H$5="All","*",Dashboard!$H$5),Monthly_Data!$C$3:$C$146,6,Monthly_Data!$F$3:$F$146,"Actual") -> 6127590 | C39: =SUMIFS(Monthly_Data!$K$3:$K$146,Monthly_Data!$B$3:$B$146,Dashboard!$D$5,Monthly_Data!$E$3:$E$146,IF(Dashboard!$H$5="All","*",Dashboard!$H$5),Monthly_Data!$C$3:$C$146,6,Monthly_Data!$F$3:$F$146,"Forecast") -> 0 | D39: =SUMIFS(Monthly_Data!$L$3:$L$146,Monthly_Data!$B$3:$B$146,Dashboard!$D$5,Monthly_Data!$E$3:$E$146,IF(Dashboard!$H$5="All","*",Dashboard!$H$5),Monthly_Data!$C$3:$C$146,6) -> 6091100 | E39: =IFERROR(SUMIFS(Monthly_Data!$I$3:$I$146,Monthly_Data!$B$3:$B$146,Dashboard!$D$5,Monthly_Data!$E$3:$E$146,IF(Dashboard!$H$5="All","*",Dashboard!$H$5),Monthly_Data!$C$3:$C$146,6)/SUMIFS(Monthly_Data!$H$3:$H$146,Monthly_Data!$B$3:$B$146,Dashboard!$D$5,Monthly_Data!$E$3:$E$146,IF(Dashboard!$H$5="All","*",Dashboard!$H$5),Monthly_Data!$C$3:$C$146,6),0) -> 0.70969539 | F39: =IFERROR(SUMIFS(Monthly_Data!$J$3:$J$146,Monthly_Data!$B$3:$B$146,Dashboard!$D$5,Monthly_Data!$E$3:$E$146,IF(Dashboard!$H$5="All","*",Dashboard!$H$5),Monthly_Data!$C$3:$C$146,6)/SUMIFS(Monthly_Data!$I$3:$I$146,Monthly_Data!$B$3:$B$146,Dashboard!$D$5,Monthly_Data!$E$3:$E$146,IF(Dashboard!$H$5="All","*",Dashboard!$H$5),Monthly_Data!$C$3:$C$146,6),0) -> 0.91562418
A40: Jul | B40: =SUMIFS(Monthly_Data!$K$3:$K$146,Monthly_Data!$B$3:$B$146,Dashboard!$D$5,Monthly_Data!$E$3:$E$146,IF(Dashboard!$H$5="All","*",Dashboard!$H$5),Monthly_Data!$C$3:$C$146,7,Monthly_Data!$F$3:$F$146,"Actual") -> 5594890 | C40: =SUMIFS(Monthly_Data!$K$3:$K$146,Monthly_Data!$B$3:$B$146,Dashboard!$D$5,Monthly_Data!$E$3:$E$146,IF(Dashboard!$H$5="All","*",Dashboard!$H$5),Monthly_Data!$C$3:$C$146,7,Monthly_Data!$F$3:$F$146,"Forecast") -> 0 | D40: =SUMIFS(Monthly_Data!$L$3:$L$146,Monthly_Data!$B$3:$B$146,Dashboard!$D$5,Monthly_Data!$E$3:$E$146,IF(Dashboard!$H$5="All","*",Dashboard!$H$5),Monthly_Data!$C$3:$C$146,7) -> 5612700 | E40: =IFERROR(SUMIFS(Monthly_Data!$I$3:$I$146,Monthly_Data!$B$3:$B$146,Dashboard!$D$5,Monthly_Data!$E$3:$E$146,IF(Dashboard!$H$5="All","*",Dashboard!$H$5),Monthly_Data!$C$3:$C$146,7)/SUMIFS(Monthly_Data!$H$3:$H$146,Monthly_Data!$B$3:$B$146,Dashboard!$D$5,Monthly_Data!$E$3:$E$146,IF(Dashboard!$H$5="All","*",Dashboard!$H$5),Monthly_Data!$C$3:$C$146,7),0) -> 0.65547885 | F40: =IFERROR(SUMIFS(Monthly_Data!$J$3:$J$146,Monthly_Data!$B$3:$B$146,Dashboard!$D$5,Monthly_Data!$E$3:$E$146,IF(Dashboard!$H$5="All","*",Dashboard!$H$5),Monthly_Data!$C$3:$C$146,7)/SUMIFS(Monthly_Data!$I$3:$I$146,Monthly_Data!$B$3:$B$146,Dashboard!$D$5,Monthly_Data!$E$3:$E$146,IF(Dashboard!$H$5="All","*",Dashboard!$H$5),Monthly_Data!$C$3:$C$146,7),0) -> 0.90403361
A41: Aug | B41: =SUMIFS(Monthly_Data!$K$3:$K$146,Monthly_Data!$B$3:$B$146,Dashboard!$D$5,Monthly_Data!$E$3:$E$146,IF(Dashboard!$H$5="All","*",Dashboard!$H$5),Monthly_Data!$C$3:$C$146,8,Monthly_Data!$F$3:$F$146,"Actual") -> 4595840 | C41: =SUMIFS(Monthly_Data!$K$3:$K$146,Monthly_Data!$B$3:$B$146,Dashboard!$D$5,Monthly_Data!$E$3:$E$146,IF(Dashboard!$H$5="All","*",Dashboard!$H$5),Monthly_Data!$C$3:$C$146,8,Monthly_Data!$F$3:$F$146,"Forecast") -> 0 | D41: =SUMIFS(Monthly_Data!$L$3:$L$146,Monthly_Data!$B$3:$B$146,Dashboard!$D$5,Monthly_Data!$E$3:$E$146,IF(Dashboard!$H$5="All","*",Dashboard!$H$5),Monthly_Data!$C$3:$C$146,8) -> 4597800 | E41: =IFERROR(SUMIFS(Monthly_Data!$I$3:$I$146,Monthly_Data!$B$3:$B$146,Dashboard!$D$5,Monthly_Data!$E$3:$E$146,IF(Dashboard!$H$5="All","*",Dashboard!$H$5),Monthly_Data!$C$3:$C$146,8)/SUMIFS(Monthly_Data!$H$3:$H$146,Monthly_Data!$B$3:$B$146,Dashboard!$D$5,Monthly_Data!$E$3:$E$146,IF(Dashboard!$H$5="All","*",Dashboard!$H$5),Monthly_Data!$C$3:$C$146,8),0) -> 0.57385936 | F41: =IFERROR(SUMIFS(Monthly_Data!$J$3:$J$146,Monthly_Data!$B$3:$B$146,Dashboard!$D$5,Monthly_Data!$E$3:$E$146,IF(Dashboard!$H$5="All","*",Dashboard!$H$5),Monthly_Data!$C$3:$C$146,8)/SUMIFS(Monthly_Data!$I$3:$I$146,Monthly_Data!$B$3:$B$146,Dashboard!$D$5,Monthly_Data!$E$3:$E$146,IF(Dashboard!$H$5="All","*",Dashboard!$H$5),Monthly_Data!$C$3:$C$146,8),0) -> 0.90401324
A42: Sep | B42: =SUMIFS(Monthly_Data!$K$3:$K$146,Monthly_Data!$B$3:$B$146,Dashboard!$D$5,Monthly_Data!$E$3:$E$146,IF(Dashboard!$H$5="All","*",Dashboard!$H$5),Monthly_Data!$C$3:$C$146,9,Monthly_Data!$F$3:$F$146,"Actual") -> 6205960 | C42: =SUMIFS(Monthly_Data!$K$3:$K$146,Monthly_Data!$B$3:$B$146,Dashboard!$D$5,Monthly_Data!$E$3:$E$146,IF(Dashboard!$H$5="All","*",Dashboard!$H$5),Monthly_Data!$C$3:$C$146,9,Monthly_Data!$F$3:$F$146,"Forecast") -> 0 | D42: =SUMIFS(Monthly_Data!$L$3:$L$146,Monthly_Data!$B$3:$B$146,Dashboard!$D$5,Monthly_Data!$E$3:$E$146,IF(Dashboard!$H$5="All","*",Dashboard!$H$5),Monthly_Data!$C$3:$C$146,9) -> 6313200 | E42: =IFERROR(SUMIFS(Monthly_Data!$I$3:$I$146,Monthly_Data!$B$3:$B$146,Dashboard!$D$5,Monthly_Data!$E$3:$E$146,IF(Dashboard!$H$5="All","*",Dashboard!$H$5),Monthly_Data!$C$3:$C$146,9)/SUMIFS(Monthly_Data!$H$3:$H$146,Monthly_Data!$B$3:$B$146,Dashboard!$D$5,Monthly_Data!$E$3:$E$146,IF(Dashboard!$H$5="All","*",Dashboard!$H$5),Monthly_Data!$C$3:$C$146,9),0) -> 0.71065154 | F42: =IFERROR(SUMIFS(Monthly_Data!$J$3:$J$146,Monthly_Data!$B$3:$B$146,Dashboard!$D$5,Monthly_Data!$E$3:$E$146,IF(Dashboard!$H$5="All","*",Dashboard!$H$5),Monthly_Data!$C$3:$C$146,9)/SUMIFS(Monthly_Data!$I$3:$I$146,Monthly_Data!$B$3:$B$146,Dashboard!$D$5,Monthly_Data!$E$3:$E$146,IF(Dashboard!$H$5="All","*",Dashboard!$H$5),Monthly_Data!$C$3:$C$146,9),0) -> 0.91640484
A43: Oct | B43: =SUMIFS(Monthly_Data!$K$3:$K$146,Monthly_Data!$B$3:$B$146,Dashboard!$D$5,Monthly_Data!$E$3:$E$146,IF(Dashboard!$H$5="All","*",Dashboard!$H$5),Monthly_Data!$C$3:$C$146,10,Monthly_Data!$F$3:$F$146,"Actual") -> 0 | C43: =SUMIFS(Monthly_Data!$K$3:$K$146,Monthly_Data!$B$3:$B$146,Dashboard!$D$5,Monthly_Data!$E$3:$E$146,IF(Dashboard!$H$5="All","*",Dashboard!$H$5),Monthly_Data!$C$3:$C$146,10,Monthly_Data!$F$3:$F$146,"Forecast") -> 6338160 | D43: =SUMIFS(Monthly_Data!$L$3:$L$146,Monthly_Data!$B$3:$B$146,Dashboard!$D$5,Monthly_Data!$E$3:$E$146,IF(Dashboard!$H$5="All","*",Dashboard!$H$5),Monthly_Data!$C$3:$C$146,10) -> 6407700 | E43: =IFERROR(SUMIFS(Monthly_Data!$I$3:$I$146,Monthly_Data!$B$3:$B$146,Dashboard!$D$5,Monthly_Data!$E$3:$E$146,IF(Dashboard!$H$5="All","*",Dashboard!$H$5),Monthly_Data!$C$3:$C$146,10)/SUMIFS(Monthly_Data!$H$3:$H$146,Monthly_Data!$B$3:$B$146,Dashboard!$D$5,Monthly_Data!$E$3:$E$146,IF(Dashboard!$H$5="All","*",Dashboard!$H$5),Monthly_Data!$C$3:$C$146,10),0) -> 0.7478954 | F43: =IFERROR(SUMIFS(Monthly_Data!$J$3:$J$146,Monthly_Data!$B$3:$B$146,Dashboard!$D$5,Monthly_Data!$E$3:$E$146,IF(Dashboard!$H$5="All","*",Dashboard!$H$5),Monthly_Data!$C$3:$C$146,10)/SUMIFS(Monthly_Data!$I$3:$I$146,Monthly_Data!$B$3:$B$146,Dashboard!$D$5,Monthly_Data!$E$3:$E$146,IF(Dashboard!$H$5="All","*",Dashboard!$H$5),Monthly_Data!$C$3:$C$146,10),0) -> 0.91025002
A44: Nov | B44: =SUMIFS(Monthly_Data!$K$3:$K$146,Monthly_Data!$B$3:$B$146,Dashboard!$D$5,Monthly_Data!$E$3:$E$146,IF(Dashboard!$H$5="All","*",Dashboard!$H$5),Monthly_Data!$C$3:$C$146,11,Monthly_Data!$F$3:$F$146,"Actual") -> 0 | C44: =SUMIFS(Monthly_Data!$K$3:$K$146,Monthly_Data!$B$3:$B$146,Dashboard!$D$5,Monthly_Data!$E$3:$E$146,IF(Dashboard!$H$5="All","*",Dashboard!$H$5),Monthly_Data!$C$3:$C$146,11,Monthly_Data!$F$3:$F$146,"Forecast") -> 6706020 | D44: =SUMIFS(Monthly_Data!$L$3:$L$146,Monthly_Data!$B$3:$B$146,Dashboard!$D$5,Monthly_Data!$E$3:$E$146,IF(Dashboard!$H$5="All","*",Dashboard!$H$5),Monthly_Data!$C$3:$C$146,11) -> 6597500 | E44: =IFERROR(SUMIFS(Monthly_Data!$I$3:$I$146,Monthly_Data!$B$3:$B$146,Dashboard!$D$5,Monthly_Data!$E$3:$E$146,IF(Dashboard!$H$5="All","*",Dashboard!$H$5),Monthly_Data!$C$3:$C$146,11)/SUMIFS(Monthly_Data!$H$3:$H$146,Monthly_Data!$B$3:$B$146,Dashboard!$D$5,Monthly_Data!$E$3:$E$146,IF(Dashboard!$H$5="All","*",Dashboard!$H$5),Monthly_Data!$C$3:$C$146,11),0) -> 0.75573593 | F44: =IFERROR(SUMIFS(Monthly_Data!$J$3:$J$146,Monthly_Data!$B$3:$B$146,Dashboard!$D$5,Monthly_Data!$E$3:$E$146,IF(Dashboard!$H$5="All","*",Dashboard!$H$5),Monthly_Data!$C$3:$C$146,11)/SUMIFS(Monthly_Data!$I$3:$I$146,Monthly_Data!$B$3:$B$146,Dashboard!$D$5,Monthly_Data!$E$3:$E$146,IF(Dashboard!$H$5="All","*",Dashboard!$H$5),Monthly_Data!$C$3:$C$146,11),0) -> 0.91402931
A45: Dec | B45: =SUMIFS(Monthly_Data!$K$3:$K$146,Monthly_Data!$B$3:$B$146,Dashboard!$D$5,Monthly_Data!$E$3:$E$146,IF(Dashboard!$H$5="All","*",Dashboard!$H$5),Monthly_Data!$C$3:$C$146,12,Monthly_Data!$F$3:$F$146,"Actual") -> 0 | C45: =SUMIFS(Monthly_Data!$K$3:$K$146,Monthly_Data!$B$3:$B$146,Dashboard!$D$5,Monthly_Data!$E$3:$E$146,IF(Dashboard!$H$5="All","*",Dashboard!$H$5),Monthly_Data!$C$3:$C$146,12,Monthly_Data!$F$3:$F$146,"Forecast") -> 5379740 | D45: =SUMIFS(Monthly_Data!$L$3:$L$146,Monthly_Data!$B$3:$B$146,Dashboard!$D$5,Monthly_Data!$E$3:$E$146,IF(Dashboard!$H$5="All","*",Dashboard!$H$5),Monthly_Data!$C$3:$C$146,12) -> 5394300 | E45: =IFERROR(SUMIFS(Monthly_Data!$I$3:$I$146,Monthly_Data!$B$3:$B$146,Dashboard!$D$5,Monthly_Data!$E$3:$E$146,IF(Dashboard!$H$5="All","*",Dashboard!$H$5),Monthly_Data!$C$3:$C$146,12)/SUMIFS(Monthly_Data!$H$3:$H$146,Monthly_Data!$B$3:$B$146,Dashboard!$D$5,Monthly_Data!$E$3:$E$146,IF(Dashboard!$H$5="All","*",Dashboard!$H$5),Monthly_Data!$C$3:$C$146,12),0) -> 0.6871545 | F45: =IFERROR(SUMIFS(Monthly_Data!$J$3:$J$146,Monthly_Data!$B$3:$B$146,Dashboard!$D$5,Monthly_Data!$E$3:$E$146,IF(Dashboard!$H$5="All","*",Dashboard!$H$5),Monthly_Data!$C$3:$C$146,12)/SUMIFS(Monthly_Data!$I$3:$I$146,Monthly_Data!$B$3:$B$146,Dashboard!$D$5,Monthly_Data!$E$3:$E$146,IF(Dashboard!$H$5="All","*",Dashboard!$H$5),Monthly_Data!$C$3:$C$146,12),0) -> 0.9065014
...
